[2016-05-09 12:02:47,505] {models.py:126} INFO - Filling up the DagBag from /Users/bruno/Development/Intelivix/etl-example/dags/update_progress.py
[2016-05-09 12:02:47,505] {models.py:204} INFO - Importing /Users/bruno/Development/Intelivix/etl-example/dags/update_progress.py
[2016-05-09 12:02:47,783] {models.py:296} INFO - Loaded DAG <DAG: update_progress>
[2016-05-09 12:02:57,402] {models.py:126} INFO - Filling up the DagBag from /Users/bruno/Development/Intelivix/etl-example/dags/update_progress.py
[2016-05-09 12:02:57,403] {models.py:204} INFO - Importing /Users/bruno/Development/Intelivix/etl-example/dags/update_progress.py
[2016-05-09 12:02:57,676] {models.py:296} INFO - Loaded DAG <DAG: update_progress>
[2016-05-09 12:02:57,844] {models.py:1001} INFO - 
--------------------------------------------------------------------------------
Attempt 1 out of 2
--------------------------------------------------------------------------------

[2016-05-09 12:02:57,875] {models.py:1041} INFO - Executing <Task(PythonOperator): load_new_data> on 2016-04-04 00:00:00
[2016-05-09 12:02:57,884] {python_operator.py:66} INFO - Done. Returned value was: None
